Workbook

Sheet couverture
B12: Statistique mensuelle
B13: de la population écrouée et détenue en France
B15: situation au | D15: 1er juillet 2014
B25: Direction de l'Administration Pénitentiaire
B27: Bureau des études et de la prospective (PMJ5)

Sheet sommaire
A1: Sommaire
B3: Page 2 | D3: Sommaire
B4: Page 3 | D4: Sommaire (suite)
B5: Page 4 | D5: Les chiffres du mois
B6: Page 5 | C6: Tableau 1 | D6: Nombre de personnes écrouées
B7: Page 6 | C7: Tableau 2 | D7: Evolution mensuelle de la population écrouée depuis deux années
B8: Page 7 | C8: Tableau 3 A, B et C | D8: Courbes d'évolutions mensuelles
B9: Page 8 | C9: Tableau 4 | D9: Evolution mensuelle de la population écrouée non hébergée depuis mai 2004
B10: Page 9 | C10: Tableau 5 | D10: Courbe d'évolution mensuelle de la population écrouée non hébergée depuis mai 2004
B11: Page 10 | C11: Tableau 6 | D11: Nombre de personnes écrouées détenues et densité de population
B12: Page 11 | C12: Tableau 7 | D12: Nombre de personnes écrouées par direction interrégionale
B13: Page 12 | C13: Tableau 8 | D13: Nombre de personnes écrouées détenues et densité de population par direction interrégionale
B14: Page 13 | C14: Tableau 9 | D14: Nombre de personnes écrouées non hébergées par direction interrégionale
B15: Page 14 | C15: Tableau 10 | D15: Densité de population selon le type d'établissement par direction interrégionale
B16: Page 15 | C16: Tableau 11 | D16: Densité de population selon le type d'établissement
B17: Page 16 | C17: Tableau 12 | D17: Répartition de la population écrouée détenue selon la catégorie pénale
... B28: Page 27 | C28: Tableau 23 | D28: Population écrouée détenue par établissement, Outre-Mer

Sheet Les chiffres du mois
A1: Les chiffres du mois | K1: =couverture!D15 -> 1er juillet 2014
A4: Ensemble des personnes sous écrou | G4: Ensemble des personnes écrouées en aménagement de peine
C6: 41821 | D6: 41456 | E6: Evolution annuelle (%) | I6: 41821 | J6: 41456 | K6: Evolution annuelle (%)
A7: Total | C7: 80720 | D7: 80700 | E7: =IF(D7>0,(C7/D7)-1,"-") -> 0.00024783147 | G7: Total | I7: =I9+I10+I11 -> 14229 | J7: =J9+J10+J11 -> 13900 | K7: =(I7/J7)-1 -> 0.023669065
A9: écroués non détenus | C9: 12425 | D9: 12131 | E9: =IF(D9>0,(C9/D9)-1,"-") -> 0.02423543 | G9: dont condamnés en semi-liberté | I9: =C16 -> 1951 | J9: =D16 -> 1993 | K9: =(I9/J9)-1 -> -0.021073758
A10: dont condamnés en placement sous surveillance électronique (aménagement de peine) | C10: 11210 | D10: 10846 | E10: =IF(D10>0,(C10/D10)-1,"-") -> 0.03356076 | G10: dont condamnés en placement sous surveillance électronique (aménagement de peine) | I10: =C10 -> 11210 | J10: =D10 -> 10846 | K10: =(I10/J10)-1 -> 0.03356076
A11: dont condamnés en placement sous surveillance électronique de fin de peine | C11: 553 | D11: 629 | E11: =IF(D11>0,(C11/D11)-1,"-") -> -0.12082671 | G11: dont condamnés en placement extérieur | I11: =C12+C17 -> 1068 | J11: =D12+D17 -> 1061 | K11: =(I11/J11)-1 -> 0.0065975495
A12: dont condamnés en placement extérieur non hébergés | C12: 662 | D12: 656 | E12: =(C12/D12)-1 -> 0.0091463415
G13: Part des aménagés sur l'ensemble des condamnés écroués (%) | I13: =(I7*100)/(C18+C17+C16+C12+C10+C11) -> 22.604731 | J13: =(J7*100)/(D18+D17+D16+D12+D10+D11) -> 21.930517
A14: écroués détenus | C14: 68295 | D14: 68569 | E14: =(C14/D14)-1 -> -0.0039959749
A15: dont prévenus | C15: 17773 | D15: 17318 | E15: =(C15/D15)-1 -> 0.026273242
A16: dont condamnés en semi-liberté | C16: 1951 | D16: 1993 | E16: =(C16/D16)-1 -> -0.021073758
A17: dont condamnés en placement extérieur hébergés | C17: 406 | D17: 405 | E17: =(C17/D17)-1 -> 0.0024691358 | G17: Nombre de matelas au sol | I17: 1197
A18: dont condamnés non aménagés | C18: =C14-C15-C16-C17 -> 48165 | D18: =D14-D15-D16-D17 -> 48853 | E18: =(C18/D18)-1 -> -0.014083066
A21: Densité carcérale
B23: - 9 établissements ou quartiers ont une densité supérieure ou égale à 200 %,
B24: - 30 établissements ou quartiers ont une densité supérieure ou égale à 150 et inférieure à 200 %,
B25: - 56 établissements ou quartiers ont une densité supérieure ou égale à 120 et inférieure à 150 %,
B26: - 30 établissements ou quartiers ont une densité supérieure ou égale à 100 et inférieure à 120 %,
B27: - 123 établissements ou quartiers ont une densité inférieure à 100 %
A29: nombre de places opérationnelles : | D29: ='tab6 densité'!D16 -> 57712

Sheet sommaire suite
B1: Page 30 | C1: Tableau 26 | D1: Nombre de personnes écrouées détenues par sexe et par direction interrégionale
B2: Page 31 | C2: Tableau 27 | D2: Nombre et pourcentage de mineurs écroués détenus
B3: Page 32 | C3: Tableau 28 | D3: Nombre et pourcentage de mineurs écroués détenus selon la catégorie pénale
B4: Page 33 | C4: Tableau 29 | D4: Évolution mensuelle du nombre de mineurs écroués, sur deux années
B5: Page 34 | C5: Tableau 30 | D5: Courbe d'évolution mensuelle du nombre de mineurs écroués, sur deux années
B6: Page 35 | C6: Tableau 31 | D6: Nombre de mineurs écroués détenus par établissement et direction interrégionale, métropole et outre-mer
B7: Page 36 | C7: Tableau 32 | D7: Nombre de mineurs écroués détenus par quartier d'établissement et direction interrégionale, métropole et outre-mer
B8: Page 37 | C8: Tableau 33 | D8: Nombre de femmes écrouées
B9: Page 38 | C9: Tableau 34 | D9: Femmes écrouées selon la catégorie pénale
B10: Page 39 | C10: Tableau 35 | D10: Evolution mensuelle du nombre de femmes écrouées depuis deux années
B11: Page 40 | C11: Tableau 36 | D11: Courbe d' évolution mensuelle du nombre de femmes écrouées depuis deux années
B12: Page 41 | C12: Tableau 37 | D12: Evolution du nombre de condamnés bénéficiant d'un aménagement de peine au 1er de chaque mois
... B15: Page 44 | C15: Tableau 40 | D15: Etablissements dont la densité carcérale est supérieure à 120%

Sheet tab1écrouées
B1: Tableau 1
B2: Nombre de personnes écrouées
B3: (détenues ou non hébergées)
A5: Champ : | B5: Métropole et Outre-Mer
A6: Effectif au : | B6: =couverture!D15 -> 1er juillet 2014
A7: Source : | B7: DAP - PMJ5
C11: Nombre de personnes écrouées détenues | D11: Nombre de personnes écrouées non hébergées | E11: Total
B12: Métropole | C12: 63684 | D12: 11868 | E12: =C12+D12 -> 75552
B14: Outre Mer | C14: 4611 | D14: 557 | E14: =C14+D14 -> 5168
B16: Ensemble des établissements pénitentiaires | C16: =SUM(C12:C14) -> 68295 | D16: =SUM(D12:D14) -> 12425 | E16: =C16+D16 -> 80720

Sheet tab2évol
B1: Tableau 2
B2: Evolution mensuelle de la population écrouée détenue sur deux années
A4: Champ : | B4: Métropole et Outre-Mer
A5: Effectif au : | B5: =couverture!D15 -> 1er juillet 2014
A6: Source : | B6: DAP - PMJ5
B8: Situation au 1er du mois | C8: Prévenus | D8: Condamnés | E8: Ensemble | F8: Variation mensuelle (%)
B9: juillet 2012 | C9: 17138 | D9: 50235 | E9: 67373 | F9: 0.68445042
B10: août 2012 | C10: 16467 | D10: 50281 | E10: 66748 | F10: -0.92767132
B11: septembre 2012 | C11: 16266 | D11: 49860 | E11: 66126 | F11: -0.93186313
B12: octobre 2012 | C12: 16915 | D12: 49789 | E12: 66704 | F12: 0.87408886
B13: novembre 2012 | C13: 16821 | D13: 50404 | E13: 67225 | F13: 0.7810626
B14: décembre 2012 | C14: 16945 | D14: 50729 | E14: 67674 | F14: 0.66790628
B15: janvier 2013 | C15: 16454 | D15: 50118 | E15: 66572 | F15: -1.628395
B16: février 2013 | C16: 16754 | D16: 49992 | E16: 66746 | F16: 0.26137115
B17: mars 2013 | C17: 16799 | D17: 50196 | E17: 66995 | F17: 0.37305606
B18: avril 2013 | C18: 17166 | D18: 50327 | E18: 67493 | F18: 0.74333906
B19: mai 2013 | C19: 16987 | D19: 50852 | E19: 67839 | F19: 0.51264576
B20: juin 2013 | C20: 17195 | D20: 50782 | E20: 67977 | F20: 0.20342281
... B33: juillet 2014 | C33: 17773 | D33: 50522 | E33: 68295 | F33: -0.51421746

Sheet tab3 courbeA
B1: Tableau 3-A
B2: Courbe d'évolution mensuelle de la population écrouée détenue depuis 20 ans
A4: Champ : | B4: Métropole et Outre-Mer
A5: Effectif au : | B5: =couverture!D15 -> 1er juillet 2014
A6: Source : | B6: DAP - PMJ5

Sheet tab3 courbeB
C1: Tableau 3-B
C2: Courbe d'évolution mensuelle de la population écrouée détenue depuis le 1er janvier 2012
A3: Evolution mensuelle de la population écrouée détenue depuis le 1er janvier 2011
B4: Champ : | C4: Métropole et Outre-Mer
B5: Effectif au : | C5: =couverture!D15 -> 1er juillet 2014
B6: Source : | C6: DAP - PMJ5

Sheet tab3 courbeC
B1: Tableau 3-C
A2: Courbe d'évolution mensuelle de la population écrouée détenue selon la catégorie pénale depuis le 1er janvier 2012
A4: Champ : | B4: Métropole et Outre-Mer
A5: Effectif au : | B5: =couverture!D15 -> 1er juillet 2014
A6: Source : | B6: DAP - PMJ5
A7: Evolution mensuelle du nombre de prévenus depuis le 1er janvier 2011 | F7: Evolution mensuelle du nombre de condamnés, depuis le 1er janvier 2011

Sheet tab4évolnheb
B1: Tableau 4
B2: Evolution mensuelle de la population écrouée non hébergée depuis 2ans
A4: Champ : | B4: Métropole et Outre-Mer
A5: Effectif au : | B5: =couverture!D15 -> 1er juillet 2014
A6: Source : | B6: DAP - PMJ5
B8: Situation au 1er du mois | C8: Nombre de personnes placées sous surveillance électronique* | D8: Dont: surveillance électronique de fin de peine | E8: Nombre de personnes placées à l'extérieur, sans hébergement | F8: Nombre de personnes écrouées non hébergées | G8: Variation mensuelle (%)
B9: juillet 2012 | C9: 10244 | D9: 617 | E9: 645 | F9: =C9+E9 -> 10889 | G9: 1.2082907
B10: août 2012 | C10: 10104 | D10: 607 | E10: 633 | F10: =C10+E10 -> 10737 | G10: -1.3959041
B11: septembre 2012 | C11: 9390 | D11: 618 | E11: 558 | F11: =C11+E11 -> 9948 | G11: -7.3484213
B12: octobre 2012 | C12: 9105 | D12: 528 | E12: 598 | F12: =C12+E12 -> 9703 | G12: -2.4628066
B13: novembre 2012 | C13: 9470 | D13: 577 | E13: 587 | F13: =C13+E13 -> 10057 | G13: 3.6483562
B14: décembre 2012 | C14: 9840 | D14: 589 | E14: 568 | F14: =C14+E14 -> 10408 | G14: 3.4901064
B15: janvier 2013 | C15: 9653 | D15: 624 | E15: 573 | F15: =C15+E15 -> 10226 | G15: -1.7486549
B16: février 2013 | C16: 10197 | D16: 625 | E16: 597 | F16: =C16+E16 -> 10794 | G16: 5.554469
B17: mars 2013 | C17: 10615 | D17: 660 | E17: 598 | F17: =C17+E17 -> 11213 | G17: 3.8817862
B18: avril 2013 | C18: 10919 | D18: 640 | E18: 585 | F18: =C18+E18 -> 11504 | G18: 2.595202
B19: mai 2013 | C19: 11438 | D19: 678 | E19: 635 | F19: =C19+E19 -> 12073 | G19: 4.9461057
B20: juin 2013 | C20: 11559 | D20: 673 | E20: 622 | F20: =C20+E20 -> 12181 | G20: 0.8945581
... B33: juillet 2014 | C33: 11763 | D33: 553 | E33: 662 | F33: =C33+E33 -> 12425 | G33: 1.6276787
B34: * y compris sous surveillance électronique de fin de peine

Sheet tab5 courbévol
B1: Tableau 5
B2: Courbe d'évolution mensuelle de la population écrouée non hébergée depuis le 1er janvier 2012
A4: Champ : | B4: Métropole et Outre-Mer
A5: Effectif au : | B5: =couverture!D15 -> 1er juillet 2014
A6: Source : | B6: DAP - PMJ5
A7: Evolution mensuelle du nombre de personnes écrouées non hébergées depuis janvier 2012

Sheet tab6 densité
B1: Tableau 6
B2: Nombre de personnes écrouées détenues et densité de population
A5: Champ : | B5: Métropole et Outre-Mer
A6: Effectif au : | B6: =couverture!D15 -> 1er juillet 2014
A7: Source : | B7: DAP - PMJ5
A8: Capacités au : | B8: =B6 -> 1er juillet 2014
B9: (source DAP - EMS1)
C11: Capacité norme circulaire | D11: Capacité opérationnelle | E11: Nombre de personnes écrouées détenues | F11: Densité (%)
B12: Métropole | C12: 54980 | D12: 53942 | E12: 63684 | F12: =E12/D12*100 -> 118.06014
B14: Outre Mer | C14: 3822 | D14: 3770 | E14: 4611 | F14: =E14/D14*100 -> 122.30769
B16: Ensemble des établissements pénitentiaires | C16: =SUM(C12:C14) -> 58802 | D16: =SUM(D12:D14) -> 57712 | E16: =SUM(E12:E14) -> 68295 | F16: =E16/D16*100 -> 118.33761
B19: Capacité norme circulaire : la circulaire A.P. 88.05G du 17 mai 1998 définit le mode de calcul de la capacité des établissements pénitentiaires.
B20: Capacité opérationnelle : correspond au nombre de places effectivement disponibles dans les établissements pénitentiaires.
B21: Densité de population : ce ratio s'obtient en rapportant le nombre de détenus présents à la capacité opérationnelle.

Sheet tab7écrouées DR
B1: Tableau 7
B2: Nombre de personnes écrouées par Direction interrégionale
B3: (détenues ou non hébergées)
A5: Champ : | B5: Métropole et Outre-Mer
A6: Effectif au : | B6: =tab1écrouées!B6 -> 1er juillet 2014
A7: Source : | B7: DAP - PMJ5
C11: Nombre de personnes écrouées détenues | D11: Nombre de personnes écrouées non hébergées
B12: Bordeaux | C12: 5180 | D12: 793
B13: Dijon | C13: 5067 | D13: 980
B14: Lille | C14: 9473 | D14: 1789
B15: Lyon | C15: 5884 | D15: 1433
B16: Marseille | C16: 7920 | D16: 1434
B17: Paris | C17: 13104 | D17: 2112
B18: Rennes | C18: 6090 | D18: 1312
B19: Strasbourg | C19: 5562 | D19: 1120
B20: Toulouse | C20: 5404 | D20: 895
B22: Ensemble de la métropole | C22: 63684 | D22: 11868
B24: Outre Mer | C24: 4611 | D24: 557
B27: Ensemble des établissements pénitentiaires | C27: 68295 | D27: 12425

Sheet tab8densité DR
B1: Tableau 8
B2: Nombre de personnes écrouées détenues et densité de population par Direction Interrégionale
A5: Champ : | B5: Métropole et Outre-Mer
A6: Effectif au : | B6: =couverture!D15 -> 1er juillet 2014
A7: Source : | B7: DAP - PMJ5
A8: Capacités au : | B8: =couverture!D15 -> 1er juillet 2014
B9: ='tab6 densité'!B9 -> (source DAP - EMS1)
C11: Capacité norme circulaire (*) | D11: Capacité opérationnelle (*) | E11: Nombre de personnes écrouées détenues | F11: Densité (%) (*)
B12: Bordeaux | C12: 5355 | D12: 5268 | E12: 5180 | F12: =E12/D12 -> 0.98329537
B13: Dijon | C13: 4855 | D13: 4743 | E13: 5067 | F13: =E13/D13 -> 1.0683112
B14: Lille | C14: 8339 | D14: 8120 | E14: 9473 | F14: =E14/D14 -> 1.1666256
B15: Lyon | C15: 5501 | D15: 5431 | E15: 5884 | F15: =E15/D15 -> 1.0834101
B16: Marseille | C16: 6196 | D16: 6154 | E16: 7920 | F16: =E16/D16 -> 1.2869678
B17: Paris | C17: 9625 | D17: 9544 | E17: 13104 | F17: =E17/D17 -> 1.3730092
B18: Rennes | C18: 5477 | D18: 5351 | E18: 6090 | F18: =E18/D18 -> 1.138105
B19: Strasbourg | C19: 5080 | D19: 4927 | E19: 5562 | F19: =E19/D19 -> 1.1288817
B20: Toulouse | C20: 4552 | D20: 4404 | E20: 5404 | F20: =E20/D20 -> 1.2270663
B22: Ensemble de la métropole | C22: 54980 | D22: 53942 | E22: 63684 | F22: =E22/D22 -> 1.1806014
B24: Outre Mer | C24: 3822 | D24: 3770 | E24: 4611 | F24: =E24/D24 -> 1.2230769
B26: Ensemble des établissements pénitentiaires | C26: =SUM(C24:C24,C22) -> 58802 | D26: =SUM(D24:D24,D22) -> 57712 | E26: =SUM(E24:E24,E22) -> 68295 | F26: =E26/D26*100 -> 118.33761
B27: (*) voir page 12

Sheet tab9non hébergées DR
B1: Tableau 9
B2: Nombre de personnes écrouées non hébergées par Direction Interrégionale
A5: Champ : | B5: Métropole et Outre-Mer
A6: Effectif au : | B6: =tab1écrouées!B6 -> 1er juillet 2014
A7: Source : | B7: DAP - PMJ5
C11: Nombre de personnes placées sous surveillance électronique en aménagement de peine | D11: Nombre de personnes placées sous surveillance électronique de fin de peine | E11: Nombre de personnes placées à l'extérieur, sans hébergement | F11: Nombre de personnes écrouées non hébergées
B12: Bordeaux | C12: 692 | D12: 52 | E12: 49 | F12: 793
B13: Dijon | C13: 910 | D13: 33 | E13: 37 | F13: 980
B14: Lille | C14: 1628 | D14: 91 | E14: 70 | F14: 1789
B15: Lyon | C15: 1323 | D15: 43 | E15: 67 | F15: 1433
B16: Marseille | C16: 1337 | D16: 67 | E16: 30 | F16: 1434
B17: Paris | C17: 1854 | D17: 98 | E17: 160 | F17: 2112
B18: Rennes | C18: 1187 | D18: 32 | E18: 93 | F18: 1312
B19: Strasbourg | C19: 976 | D19: 48 | E19: 96 | F19: 1120
B20: Toulouse | C20: 822 | D20: 38 | E20: 35 | F20: 895
B22: Ensemble de la métropole | C22: 10729 | D22: 502 | E22: 637 | F22: 11868
B24: Outre Mer | C24: 481 | D24: 51 | E24: 25 | F24: 557
B27: Ensemble des établissements pénitentiaires | C27: =SUM(C22,C24) -> 11210 | D27: =SUM(D22,D24) -> 553 | E27: =SUM(E22,E24) -> 662 | F27: =SUM(F22,F24:F25) -> 12425

Sheet tab10densité.DR.ets
B1: Tableau 10
B2: Densité de population selon le type d'établissement par Direction Interrégionale
A5: Champ : | B5: Métropole et Outre-Mer
A6: Effectif au : | B6: =couverture!D15 -> 1er juillet 2014
A7: Source : | B7: DAP - PMJ5
A8: Capacités au : | B8: =couverture!D15 -> 1er juillet 2014
B9: ='tab6 densité'!B9 -> (source DAP - EMS1)
C11: Densité Maisons d'Arrêt et Etablissement pour Mineurs (%) | D11: Densité établissements pour peine (%) (**) | E11: Densité totale (%) (*)
B12: Bordeaux | C12: 1.1203147 | D12: 0.88799485 | E12: 0.98329537
B13: Dijon | C13: 1.2983508 | D13: 0.90043764 | E13: 1.0683112
B14: Lille | C14: 1.3612497 | D14: 0.91113643 | E14: 1.1666256
B15: Lyon | C15: 1.1711373 | D15: 0.89136817 | E15: 1.0834101
B16: Marseille | C16: 1.5115865 | D16: 0.8908846 | E16: 1.2869678
B17: Paris | C17: 1.4825313 | D17: 0.94895355 | E17: 1.3730092
B18: Rennes | C18: 1.3625577 | D18: 0.84419508 | E18: 1.138105
B19: Strasbourg | C19: 1.3476228 | D19: 0.89114782 | E19: 1.1288817
B20: Toulouse | C20: 1.4132201 | D20: 0.92983491 | E20: 1.2270663
B22: Ensemble de la métropole | C22: 1.3694421 | D22: 0.89834898 | E22: 1.1806014
B24: Outre mer | C24: 1.3162814 | D24: 1.1139896 | E24: 1.2230769
B27: Ensemble des établissements pénitentiaires | C27: 1.366296 | D27: 0.91438356 | E27: 1.1833761
B28: (*) voir page 12
B29: (**) MC, CD, CPA, qMC, qCD, qCPA et CSL autonomes.

Sheet tab11typed'ets
B1: Tableau 11
B2: Densité de population selon le type d'établissement
A5: Champ : | B5: Métropole et Outre-Mer
A6: Effectif au : | B6: =couverture!D15 -> 1er juillet 2014
A7: Source : | B7: DAP - PMJ5
A8: Capacités au : | B8: =couverture!D15 -> 1er juillet 2014
B9: (source DAP - EMS1 )
B13: Type d'établissement | C13: Capacité norme circulaire (*) | D13: Capacité opérationnelle (*) | E13: Nombre de personnes détenues | F13: Densité (%) (*)
B14: MA et qMA | C14: 34224 | D14: 33999 | E14: 46657 | F14: =E14/D14*100 -> 137.23051
B15: CD et qCD | C15: 19893 | D15: 19370 | E15: 18199 | F15: =E15/D15*100 -> 93.954569
B16: MC et qMC | C16: 2453 | D16: 2167 | E16: 1723 | F16: =E16/D16*100 -> 79.510844
B17: CPA et qCPA | C17: 609 | D17: 609 | E17: 430 | F17: =E17/D17*100 -> 70.607553
B18: CSL et qCSL (**) | C18: 945 | D18: 896 | E18: 790 | F18: =E18/D18*100 -> 88.169643
B19: EPM | C19: 357 | D19: 353 | E19: 278 | F19: =E19/D19*100 -> 78.753541
B20: CNE et qCNE | C20: 321 | D20: 318 | E20: 218 | F20: =E20/D20*100 -> 68.553459
B21: Ensemble | C21: =SUM(C14:C20) -> 58802 | D21: =SUM(D14:D20) -> 57712 | E21: =SUM(E14:E20) -> 68295 | F21: =E21/D21*100 -> 118.33761
B22: q = quartier
B23: (*) voir page 12
B24: (**) hors places de SL disponibles dans d'autres établissements (MA, qMA, qCD, MC)

Sheet tab12 catpénale
B1: Tableau 12
B2: Répartition de la population écrouée détenue selon la catégorie pénale
A5: Champ : | B5: Métropole et Outre-Mer
A6: Effectif au : | B6: =couverture!D15 -> 1er juillet 2014
A7: Source : | B7: DAP - PMJ5
A10: Catégorie pénale actuelle | B10: Métropole | E10: Outre-Mer | H10: Ensemble de la population écrouée détenue
B11: Hommes | C11: Femmes | D11: Ensemble | E11: Hommes | F11: Femmes | G11: Ensemble | H11: Hommes | I11: Femmes | J11: Ensemble
A14: Prévenus | B14: 15866 | C14: 771 | D14: =SUM(B14:C14) -> 16637 | E14: 1100 | F14: 36 | G14: =SUM(E14:F14) -> 1136 | H14: =+B14+E14 -> 16966 | I14: =+C14+F14 -> 807 | J14: =+H14+I14 -> 17773
A19: Condamnés | B19: 45670 | C19: 1377 | D19: =SUM(B19:C19) -> 47047 | E19: 3377 | F19: 98 | G19: =SUM(E19:F19) -> 3475 | H19: =+B19+E19 -> 49047 | I19: =+C19+F19 -> 1475 | J19: =+H19+I19 -> 50522
A22: Ensemble | B22: =SUM(B19,B14) -> 61536 | C22: =SUM(C19,C14) -> 2148 | D22: =SUM(D19,D14) -> 63684 | E22: =SUM(E19,E14) -> 4477 | F22: =SUM(F19,F14) -> 134 | G22: =SUM(G19,G14) -> 4611 | H22: =SUM(H19,H14) -> 66013 | I22: =SUM(I19,I14) -> 2282 | J22: =SUM(J19,J14) -> 68295

Sheet tab13répart.cat.pén.
B1: Tableau 13
B2: Répartition de la population écrouée détenue selon la catégorie pénale et par Direction Interrégionale
A5: Champ : | B5: Métropole et Outre-Mer
A6: Effectif au : | B6: =couverture!D15 -> 1er juillet 2014
A7: Source : | B7: DAP - PMJ5
C11: Prévenus | D11: Condamnés | E11: Nombre de personnes écrouées détenues | F11: Taux de prévenus (%)
B12: Bordeaux | C12: 1110 | D12: 4070 | E12: =SUM(C12:D12) -> 5180 | F12: =C12/E12*100 -> 21.428571
B13: Dijon | C13: 1072 | D13: 3995 | E13: =SUM(C13:D13) -> 5067 | F13: =C13/E13*100 -> 21.156503
B14: Lille | C14: 1817 | D14: 7656 | E14: =SUM(C14:D14) -> 9473 | F14: =C14/E14*100 -> 19.18083
B15: Lyon | C15: 1486 | D15: 4398 | E15: =SUM(C15:D15) -> 5884 | F15: =C15/E15*100 -> 25.254929
B16: Marseille | C16: 2164 | D16: 5756 | E16: =SUM(C16:D16) -> 7920 | F16: =C16/E16*100 -> 27.323232
B17: Paris | C17: 4610 | D17: 8494 | E17: =SUM(C17:D17) -> 13104 | F17: =C17/E17*100 -> 35.180098
B18: Rennes | C18: 1420 | D18: 4670 | E18: =SUM(C18:D18) -> 6090 | F18: =C18/E18*100 -> 23.316913
B19: Strasbourg | C19: 1314 | D19: 4248 | E19: =SUM(C19:D19) -> 5562 | F19: =C19/E19*100 -> 23.624595
B20: Toulouse | C20: 1644 | D20: 3760 | E20: =SUM(C20:D20) -> 5404 | F20: =C20/E20*100 -> 30.42191
B22: Ensemble de la métropole | C22: =SUM(C12:C20) -> 16637 | D22: =SUM(D12:D20) -> 47047 | E22: =SUM(C22:D22) -> 63684 | F22: =C22/E22*100 -> 26.124301
B24: Outre Mer | C24: 1136 | D24: 3475 | E24: =SUM(C24:D24) -> 4611 | F24: =C24/E24*100 -> 24.636738
B27: Ensemble des établissements pénitentiaires | C27: =SUM(C24:C25,C22) -> 17773 | D27: =SUM(D24:D25,D22) -> 50522 | E27: =SUM(E24:E25,E22) -> 68295 | F27: =C27/E27*100 -> 26.023867

Sheet tab14 Bordeaux
B1: Tableau 14
B2: Population écrouée détenue par établissement | F2: Direction Interrégionale de Bordeaux
A4: Effectif au : | B4: =couverture!D15 -> 1er juillet 2014
A5: Source : | B5: DAP - PMJ5
A6: Capacités au : | B6: =couverture!D15 -> 1er juillet 2014
B7: (source DAP - EMS1 )
D8: Capacité norme circulaire | E8: Capacité opérationnelle | F8: Nombre de personnes écrouées détenues | G8: Densité (%)
B9: MA | C9: Agen | D9: 146 | E9: 146 | F9: 157 | G9: =IF(E9=0,0,F9/E9*100) -> 107.53425
B10: MA | C10: Angoulême | D10: 238 | E10: 234 | F10: 189 | G10: =IF(E10=0,0,F10/E10*100) -> 80.769231
B11: MA | C11: Bayonne | D11: 75 | E11: 75 | F11: 103 | G11: =IF(E11=0,0,F11/E11*100) -> 137.33333
B12: MA | C12: Guéret | D12: 37 | E12: 37 | F12: 36 | G12: =IF(E12=0,0,F12/E12*100) -> 97.297297
B13: MA | C13: Limoges | D13: 85 | E13: 85 | F13: 118 | G13: =IF(E13=0,0,F13/E13*100) -> 138.82353
B14: MA | C14: Niort | D14: 66 | E14: 66 | F14: 86 | G14: =IF(E14=0,0,F14/E14*100) -> 130.30303
B15: MA | C15: Pau | D15: 266 | E15: 266 | F15: 229 | G15: =IF(E15=0,0,F15/E15*100) -> 86.090226
B16: MA | C16: Périgueux | D16: 91 | E16: 91 | F16: 93 | G16: =IF(E16=0,0,F16/E16*100) -> 102.1978
B17: MA | C17: Rochefort | D17: 51 | E17: 51 | F17: 78 | G17: =IF(E17=0,0,F17/E17*100) -> 152.94118
B18: MA | C18: Saintes | D18: 83 | E18: 60 | F18: 84 | G18: =IF(E18=0,0,F18/E18*100) -> 140
B19: MA | C19: Tulle | D19: 47 | E19: 47 | F19: 67 | G19: =IF(E19=0,0,F19/E19*100) -> 142.55319
B20: qMA | C20: Bordeaux Gradignan | D20: 366 | E20: 365 | F20: 612 | G20: =IF(E20=0,0,F20/E20*100) -> 167.67123
... B22: qMA | C22: Poitiers-Vivonne | D22: 305 | E22: 305 | F22: 336 | G22: =IF(E22=0,0,F22/E22*100) -> 110.16393
B23: Ensemble des Maisons d'Arrêt et qMA | D23: 2189 | E23: 2161 | F23: 2421 | G23: =IF(E23=0,0,F23/E23*100) -> 112.03147
B24: CD | C24: Bédenac | D24: 214 | E24: 214 | F24: 155 | G24: =IF(E24=0,0,F24/E24*100) -> 72.429907
B25: CD | C25: Eysses | D25: 294 | E25: 279 | F25: 245 | G25: =IF(E25=0,0,F25/E25*100) -> 87.81362
B26: CD | C26: Mauzac | D26: 369 | E26: 369 | F26: 344 | G26: =IF(E26=0,0,F26/E26*100) -> 93.224932
B27: CD | C27: Neuvic | D27: 398 | E27: 398 | F27: 361 | G27: =IF(E27=0,0,F27/E27*100) -> 90.703518
B28: CD | C28: Uzerche | D28: 594 | E28: 590 | F28: 559 | G28: =IF(E28=0,0,F28/E28*100) -> 94.745763
B29: qCD | C29: Mont-de-Marsan | D29: 368 | E29: 368 | F29: 361 | G29: =IF(E29=0,0,F29/E29*100) -> 98.097826
B30: qCD | C30: Poitiers-Vivonne | D30: 271 | E30: 271 | F30: 263 | G30: =IF(E30=0,0,F30/E30*100) -> 97.04797
B31: MC | C31: Saint-Martin-de-Ré | D31: 500 | E31: 460 | F31: 393 | G31: =IF(E31=0,0,F31/E31*100) -> 85.434783
B32: qCPA | C32: Bordeaux Gradignan | D32: 82 | E32: 82 | F32: 67 | G32: =IF(E32=0,0,F32/E32*100) -> 81.707317
B33: qCPA | C33: Poitiers-Vivonne | D33: 27 | E33: 27 | F33: 2 | G33: =IF(E33=0,0,F33/E33*100) -> 7.4074074
B34: qCSL | C34: Mont-de-Marsan | D34: 19 | E34: 19 | F34: 2 | G34: =IF(E34=0,0,F34/E34*100) -> 10.526316
B35: qCSL | C35: Poitiers-Vivonne | D35: 30 | E35: 30 | F35: 7 | G35: =IF(E35=0,0,F35/E35*100) -> 23.333333
B36: Ensemble des établissements pour peine* | D36: 3166 | E36: 3107 | F36: 2759 | G36: =IF(E36=0,0,F36/E36*100) -> 88.799485
B37: Ensemble de la Direction Régionale | D37: 5355 | E37: 5268 | F37: 5180 | G37: =IF(E37=0,0,F37/E37*100) -> 98.329537
B38: q = quartier
B39: *article D70 du code de procédure pénale

Sheet tab15 Dijon
B1: Tableau 15
B2: Population écrouée détenue par établissement | F2: Direction Interrégionale de Dijon
A4: Effectif au : | B4: =couverture!D15 -> 1er juillet 2014
A5: Source : | B5: DAP - PMJ5
A6: Capacités au : | B6: =couverture!D15 -> 1er juillet 2014
B7: (source DAP - EMS1)
D8: Capacité norme circulaire | E8: Capacité opérationnelle | F8: Nombre de personnes écrouées détenues | G8: Densité (%)
B9: MA | C9: Auxerre | D9: 88 | E9: 88 | F9: 169 | G9: =IF(E9=0,0,F9/E9*100) -> 192.04545
B10: MA | C10: Blois | D10: 114 | E10: 114 | F10: 117 | G10: =IF(E10=0,0,F10/E10*100) -> 102.63158
B11: MA | C11: Bourges | D11: 116 | E11: 116 | F11: 143 | G11: =IF(E11=0,0,F11/E11*100) -> 123.27586
B12: MA | C12: Châlons-en-Champagne | D12: 313 | E12: 313 | F12: 344 | G12: =IF(E12=0,0,F12/E12*100) -> 109.90415
B13: MA | C13: Charleville-Mézières | D13: 59 | E13: 59 | F13: 55 | G13: =IF(E13=0,0,F13/E13*100) -> 93.220339
B14: MA | C14: Chartres | D14: 112 | E14: 112 | F14: 129 | G14: =IF(E14=0,0,F14/E14*100) -> 115.17857
B15: MA | C15: Chaumont | D15: 78 | E15: 78 | F15: 100 | G15: =IF(E15=0,0,F15/E15*100) -> 128.20513
B16: MA | C16: Dijon | D16: 185 | E16: 185 | F16: 265 | G16: =IF(E16=0,0,F16/E16*100) -> 143.24324
B17: MA | C17: Nevers | D17: 118 | E17: 118 | F17: 111 | G17: =IF(E17=0,0,F17/E17*100) -> 94.067797
B18: MA | C18: Orléans | D18: 105 | E18: 105 | F18: 280 | G18: =IF(E18=0,0,F18/E18*100) -> 266.66667
B19: MA | C19: Reims | D19: 154 | E19: 154 | F19: 154 | G19: =IF(E19=0,0,F19/E19*100) -> 100
B20: MA | C20: Tours | D20: 145 | E20: 145 | F20: 209 | G20: =IF(E20=0,0,F20/E20*100) -> 144.13793
... B23: qMA | C23: Varennes-le-Grand | D23: 193 | E23: 193 | F23: 250 | G23: =IF(E23=0,0,F23/E23*100) -> 129.53368
B24: Ensemble des Maisons d'Arrêt et qMA | D24: 2001 | E24: 2001 | F24: 2598 | G24: =IF(E24=0,0,F24/E24*100) -> 129.83508
B25: CD | C25: Châteaudun | D25: 597 | E25: 597 | F25: 548 | G25: =IF(E25=0,0,F25/E25*100) -> 91.792295
B26: CD | C26: Joux-la-Ville | D26: 602 | E26: 602 | F26: 567 | G26: =IF(E26=0,0,F26/E26*100) -> 94.186047
B27: CD | C27: Villenauxe-la-Grande | D27: 606 | E27: 606 | F27: 562 | G27: =IF(E27=0,0,F27/E27*100) -> 92.739274
B28: qCD | C28: Châteauroux | D28: 270 | E28: 257 | F28: 240 | G28: =IF(E28=0,0,F28/E28*100) -> 93.385214
B29: qCD | C29: Varennes-le-Grand | D29: 191 | E29: 191 | F29: 181 | G29: =IF(E29=0,0,F29/E29*100) -> 94.764398
B30: MC | C30: Clairvaux | D30: 238 | E30: 209 | F30: 148 | G30: =IF(E30=0,0,F30/E30*100) -> 70.813397
B31: MC | C31: Saint Maur | D31: 330 | E31: 260 | F31: 216 | G31: =IF(E31=0,0,F31/E31*100) -> 83.076923
B32: CSL | C32: Montargis | D32: 20 | E32: 20 | F32: 7 | G32: =IF(E32=0,0,F32/E32*100) -> 35
B33: Ensemble des établissements pour peine* | D33: 2854 | E33: 2742 | F33: 2469 | G33: =IF(E33=0,0,F33/E33*100) -> 90.043764
B34: Ensemble de la Direction Régionale | D34: 4855 | E34: 4743 | F34: 5067 | G34: =IF(E34=0,0,F34/E34*100) -> 106.83112
B35: q = quartier
B36: *article D70 du code de procédure pénale

Sheet tab16 Lille
B1: Tableau 16
B2: Population écrouée détenue par établissement | F2: Direction Interrégionale de Lille
A4: Effectif au : | B4: =couverture!D15 -> 1er juillet 2014
A5: Source : | B5: DAP - PMJ5
A6: Capacités au : | B6: =couverture!D15 -> 1er juillet 2014
B7: (source DAP - EMS1)
D8: Capacité norme circulaire | E8: Capacité opérationnelle | F8: Nombre de personnes écrouées détenues | G8: Densité (%)
B9: MA | C9: Amiens | D9: 307 | E9: 307 | F9: 474 | G9: =IF(E9=0,0,F9/E9*100) -> 154.39739
B10: MA | C10: Arras | D10: 202 | E10: 202 | F10: 276 | G10: =IF(E10=0,0,F10/E10*100) -> 136.63366
B11: MA | C11: Beauvais | D11: 117 | E11: 117 | F11: 145 | G11: =IF(E11=0,0,F11/E11*100) -> 123.93162
B12: MA | C12: Béthune | D12: 180 | E12: 167 | F12: 370 | G12: =IF(E12=0,0,F12/E12*100) -> 221.55689
B13: MA | C13: Compiègne | D13: 82 | E13: 82 | F13: 83 | G13: =IF(E13=0,0,F13/E13*100) -> 101.21951
B14: MA | C14: Douai | D14: 385 | E14: 385 | F14: 556 | G14: =IF(E14=0,0,F14/E14*100) -> 144.41558
B15: MA | C15: Dunkerque | D15: 105 | E15: 105 | F15: 111 | G15: =IF(E15=0,0,F15/E15*100) -> 105.71429
B16: MA | C16: Evreux | D16: 162 | E16: 162 | F16: 257 | G16: =IF(E16=0,0,F16/E16*100) -> 158.64198
B17: MA | C17: Rouen | D17: 647 | E17: 647 | F17: 623 | G17: =IF(E17=0,0,F17/E17*100) -> 96.290572
B18: MA | C18: Valenciennes | D18: 222 | E18: 222 | F18: 359 | G18: =IF(E18=0,0,F18/E18*100) -> 161.71171
B19: qMA | C19: Laon | D19: 195 | E19: 195 | F19: 306 | G19: =IF(E19=0,0,F19/E19*100) -> 156.92308
B20: qMA | C20: Le Havre | D20: 298 | E20: 297 | F20: 336 | G20: =IF(E20=0,0,F20/E20*100) -> 113.13131
... B26: qMA | C26: Lille-Loos-Séquedin (Lille-Séquedin) | D26: 584 | E26: 584 | F26: 862 | G26: =IF(E26=0,0,F26/E26*100) -> 147.60274
B27: Ensemble des Maisons d'Arrêt et qMA | D27: 4631 | E27: 4549 | F27: 6223 | G27: =IF(E27=0,0,F27/E27*100) -> 136.7993
B28: CD | C28: Bapaume | D28: 599 | E28: 599 | F28: 529 | G28: =IF(E28=0,0,F28/E28*100) -> 88.313856
B29: CD | C29: Val-de-Reuil | D29: 819 | E29: 780 | F29: 761 | G29: =IF(E29=0,0,F29/E29*100) -> 97.564103
B30: qCD | C30: Château-Thierry | D30: 33 | E30: 33 | F30: 27 | G30: =IF(E30=0,0,F30/E30*100) -> 81.818182
B31: qCD | C31: Laon | D31: 200 | E31: 200 | F31: 189 | G31: =IF(E31=0,0,F31/E31*100) -> 94.5
B32: qCD | C32: Le Havre | D32: 392 | E32: 391 | F32: 362 | G32: =IF(E32=0,0,F32/E32*100) -> 92.58312
B33: qCD | C33: Liancourt | D33: 384 | E33: 384 | F33: 362 | G33: =IF(E33=0,0,F33/E33*100) -> 94.270833
B34: qCD | C34: Lille-Annoeullin | D34: 209 | E34: 209 | F34: 197 | G34: =IF(E34=0,0,F34/E34*100) -> 94.258373
B35: qCD | C35: Longuenesse | D35: 400 | E35: 400 | F35: 387 | G35: =IF(E35=0,0,F35/E35*100) -> 96.75
B36: qCD | C36: Maubeuge | D36: 200 | E36: 200 | F36: 190 | G36: =IF(E36=0,0,F36/E36*100) -> 95
B37: qCD | C37: Liancourt | D37: 94 | E37: 0 | F37: 0 | G37: =IF(E37=0,0,F37/E37*100) -> 0
B38: qMC | C38: Château-Thierry | D38: 101 | E38: 101 | F38: 74 | G38: =IF(E38=0,0,F38/E38*100) -> 73.267327
B39: qMC | C39: Lille-Annoeullin | D39: 28 | E39: 28 | F39: 24 | G39: =IF(E39=0,0,F39/E39*100) -> 85.714286
... B43: qCNE | C43: Lille-Loos-Séquedin | D43: 33 | E43: 30 | F43: 27 | G43: =IF(E43=0,0,F43/E43*100) -> 90
B44: Ensemble des établissements pour peine* | D44: 3708 | E44: 3571 | F44: 3250 | G44: =IF(E44=0,0,F44/E44*100) -> 91.010921
B45: Ensemble de la Direction Régionale | D45: 8339 | E45: 8120 | F45: 9473 | G45: =IF(E45=0,0,F45/E45*100) -> 116.66256
B46: q = quartier
B47: *article D70 du code de procédure pénale

Sheet tab17 Lyon
B1: Tableau 17
B2: Population écrouée détenue par établissement | F2: Direction Interrégionale de Lyon
A4: Effectif au : | B4: =couverture!D15 -> 1er juillet 2014
A5: Source : | B5: DAP - PMJ5
A6: Capacités au : | B6: =couverture!D15 -> 1er juillet 2014
B7: (source DAP - EMS1)
D8: Capacité norme circulaire | E8: Capacité opérationnelle | F8: Nombre de personnes écrouées détenues | G8: Densité (%)
B9: MA | C9: Aurillac | D9: 72 | E9: 72 | F9: 47 | G9: =IF(E9=0,0,F9/E9*100) -> 65.277778
B10: MA | C10: Bonneville | D10: 187 | E10: 187 | F10: 220 | G10: =IF(E10=0,0,F10/E10*100) -> 117.64706
B11: MA | C11: Chambéry | D11: 93 | E11: 93 | F11: 126 | G11: =IF(E11=0,0,F11/E11*100) -> 135.48387
B12: MA | C12: Clermont-Ferrand | D12: 70 | E12: 70 | F12: 79 | G12: =IF(E12=0,0,F12/E12*100) -> 112.85714
B13: MA | C13: Grenoble | D13: 232 | E13: 232 | F13: 309 | G13: =IF(E13=0,0,F13/E13*100) -> 133.18966
B14: MA | C14: Le-Puy-en-Velay | D14: 36 | E14: 36 | F14: 61 | G14: =IF(E14=0,0,F14/E14*100) -> 169.44444
B15: MA | C15: Lyon Corbas | D15: 688 | E15: 688 | F15: 898 | G15: =IF(E15=0,0,F15/E15*100) -> 130.52326
B16: MA | C16: Montluçon | D16: 21 | E16: 21 | F16: 28 | G16: =IF(E16=0,0,F16/E16*100) -> 133.33333
B17: MA | C17: Privas | D17: 62 | E17: 62 | F17: 70 | G17: =IF(E17=0,0,F17/E17*100) -> 112.90323
B18: MA | C18: Riom | D18: 141 | E18: 141 | F18: 114 | G18: =IF(E18=0,0,F18/E18*100) -> 80.851064
B19: MA | C19: Saint Etienne-la-Talaudière | D19: 327 | E19: 327 | F19: 399 | G19: =IF(E19=0,0,F19/E19*100) -> 122.01835
B20: MA | C20: Valence | D20: 137 | E20: 137 | F20: 169 | G20: =IF(E20=0,0,F20/E20*100) -> 123.35766
... B25: qMA | C25: Saint-Quentin-Fallavier | D25: 237 | E25: 237 | F25: 304 | G25: =IF(E25=0,0,F25/E25*100) -> 128.27004
B26: Ensemble des Maisons d'Arrêt et qMA | D26: 3688 | E26: 3668 | F26: 4334 | G26: =IF(E26=0,0,F26/E26*100) -> 118.15703
B27: CD | C27: Riom | D27: 163 | E27: 163 | F27: 147 | G27: =IF(E27=0,0,F27/E27*100) -> 90.184049
B28: CD | C28: Roanne | D28: 599 | E28: 599 | F28: 503 | G28: =IF(E28=0,0,F28/E28*100) -> 83.973289
B29: qCD | C29: Aiton | D29: 200 | E29: 150 | F29: 146 | G29: =IF(E29=0,0,F29/E29*100) -> 97.333333
B30: qCD | C30: Bourg-en-Bresse | D30: 300 | E30: 300 | F30: 288 | G30: =IF(E30=0,0,F30/E30*100) -> 96
B31: qCD | C31: Saint-Quentin-Fallavier | D31: 192 | E31: 192 | F31: 177 | G31: =IF(E31=0,0,F31/E31*100) -> 92.1875
B32: qMC | C32: Moulins Yzeure | D32: 123 | E32: 123 | F32: 107 | G32: =IF(E32=0,0,F32/E32*100) -> 86.99187
B33: CSL | C33: Grenoble | D33: 36 | E33: 36 | F33: 37 | G33: =IF(E33=0,0,F33/E33*100) -> 102.77778
B34: CSL | C34: Lyon | D34: 100 | E34: 100 | F34: 82 | G34: =IF(E34=0,0,F34/E34*100) -> 82
B35: qCSL | C35: Bourg-en-Bresse | D35: 40 | E35: 40 | F35: 31 | G35: =IF(E35=0,0,F35/E35*100) -> 77.5
B36: EPM | C36: Rhône | D36: 60 | E36: 60 | F36: 32 | G36: =IF(E36=0,0,F36/E36*100) -> 53.333333
B37: Ensemble des établissements pour peine* | D37: 1813 | E37: 1763 | F37: 1550 | G37: =IF(E37=0,0,F37/E37*100) -> 87.918321
B38: Ensemble de la Direction Régionale | D38: 5501 | E38: 5431 | F38: 5884 | G38: =IF(E38=0,0,F38/E38*100) -> 108.34101
B39: q = quartier
B40: *article D70 du code de procédure pénale

Sheet tab18 marseille
B1: Tableau 18
B2: Population écrouée détenue par établissement | F2: Direction Interrégionale de Marseille
A4: Effectif au : | B4: =couverture!D15 -> 1er juillet 2014
A5: Source : | B5: DAP - PMJ5
A6: Capacités au : | B6: =couverture!D15 -> 1er juillet 2014
B7: (source DAP - EMS1)
D8: Capacité norme circulaire | E8: Capacité opérationnelle | F8: Nombre de personnes écrouées détenues | G8: Densité (%)
B9: MA | C9: Ajaccio | D9: 53 | E9: 53 | F9: 62 | G9: =IF(E9=0,0,F9/E9*100) -> 116.98113
B10: MA | C10: Digne | D10: 35 | E10: 35 | F10: 34 | G10: =IF(E10=0,0,F10/E10*100) -> 97.142857
B11: MA | C11: Gap | D11: 37 | E11: 37 | F11: 31 | G11: =IF(E11=0,0,F11/E11*100) -> 83.783784
B12: MA | C12: Grasse | D12: 573 | E12: 573 | F12: 799 | G12: =IF(E12=0,0,F12/E12*100) -> 139.44154
B13: MA | C13: Nice | D13: 363 | E13: 363 | F13: 609 | G13: =IF(E13=0,0,F13/E13*100) -> 167.7686
B14: qMA | C14: Aix-Luynes | D14: 612 | E14: 612 | F14: 918 | G14: =IF(E14=0,0,F14/E14*100) -> 150
B15: qMA | C15: Avignon le Pontet | D15: 420 | E15: 420 | F15: 589 | G15: =IF(E15=0,0,F15/E15*100) -> 140.2381
B16: qMA | C16: Borgo | D16: 183 | E16: 183 | F16: 213 | G16: =IF(E16=0,0,F16/E16*100) -> 116.39344
B17: qMA | C17: Marseille-Les-Baumettes | D17: 1197 | E17: 1197 | F17: 1932 | G17: =IF(E17=0,0,F17/E17*100) -> 161.40351
B18: qMA | C18: Toulon-la-Farlède | D18: 395 | E18: 395 | F18: 690 | G18: =IF(E18=0,0,F18/E18*100) -> 174.68354
B19: Ensemble des Maisons d'Arrêt et qMA | D19: 3868 | E19: 3868 | F19: 5877 | G19: =IF(E19=0,0,F19/E19*100) -> 151.93899
B20: CD | C20: Casabianda | D20: 194 | E20: 194 | F20: 126 | G20: =IF(E20=0,0,F20/E20*100) -> 64.948454
B21: CD | C21: Salon-de-Provence | D21: 650 | E21: 650 | F21: 635 | G21: =IF(E21=0,0,F21/E21*100) -> 97.692308
B22: CD | C22: Tarascon | D22: 651 | E22: 650 | F22: 631 | G22: =IF(E22=0,0,F22/E22*100) -> 97.076923
B23: qCD | C23: Avignon le Pontet | D23: 180 | E23: 180 | F23: 178 | G23: =IF(E23=0,0,F23/E23*100) -> 98.888889
B24: qCD | C24: Borgo | D24: 48 | E24: 48 | F24: 44 | G24: =IF(E24=0,0,F24/E24*100) -> 91.666667
B25: qCD | C25: Marseille-Les-Baumettes | D25: 38 | E25: 0 | F25: 0 | G25: =IF(E25=0,0,F25/E25*100) -> 0
B26: qCD | C26: Toulon-la-Farlède | D26: 191 | E26: 191 | F26: 159 | G26: =IF(E26=0,0,F26/E26*100) -> 83.246073
B27: MC | C27: Arles | D27: 160 | E27: 157 | F27: 133 | G27: =IF(E27=0,0,F27/E27*100) -> 84.713376
B28: qCPA | C28: Aix-Luynes | D28: 82 | E28: 82 | F28: 42 | G28: =IF(E28=0,0,F28/E28*100) -> 51.219512
B29: qCPA | C29: Marseille-Les-Baumettes | D29: 24 | E29: 24 | F29: 0 | G29: =IF(E29=0,0,F29/E29*100) -> 0
B30: qCSL | C30: Avignon le Pontet | D30: 51 | E30: 51 | F30: 36 | G30: =IF(E30=0,0,F30/E30*100) -> 70.588235
B31: EPM | C31: Marseille | D31: 59 | E31: 59 | F31: 59 | G31: =IF(E31=0,0,F31/E31*100) -> 100
B32: Ensemble des établissements pour peine* | D32: 2328 | E32: 2286 | F32: 2043 | G32: =IF(E32=0,0,F32/E32*100) -> 89.370079
B33: Ensemble de la Direction Régionale | D33: 6196 | E33: 6154 | F33: 7920 | G33: =IF(E33=0,0,F33/E33*100) -> 128.69678
B34: q = quartier
B35: *article D70 du code de procédure pénale

Sheet tab19 paris
B1: Tableau 19
B2: Population écrouée détenue par établissement | F2: Direction Interrégionale de Paris
A4: Effectif au : | B4: =couverture!D15 -> 1er juillet 2014
A5: Source : | B5: DAP - PMJ5
A6: Capacités au : | B6: =couverture!D15 -> 1er juillet 2014
B7: (source DAP - EMS1)
D8: Capacité norme circulaire | E8: Capacité opérationnelle | F8: Nombre de personnes écrouées détenues | G8: Densité (%)
B9: MA | C9: Bois d'Arcy | D9: 500 | E9: 500 | F9: 833 | G9: =IF(E9=0,0,F9/E9*100) -> 166.6
B10: MA | C10: Fleury-Mérogis | D10: 2857 | E10: 2857 | F10: 4036 | G10: =IF(E10=0,0,F10/E10*100) -> 141.26706
B11: MA | C11: Nanterre | D11: 592 | E11: 592 | F11: 1054 | G11: =IF(E11=0,0,F11/E11*100) -> 178.04054
B12: MA | C12: Osny-Pontoise | D12: 579 | E12: 579 | F12: 874 | G12: =IF(E12=0,0,F12/E12*100) -> 150.94991
B13: MA | C13: Paris-La-Santé | D13: 483 | E13: 483 | F13: 195 | G13: =IF(E13=0,0,F13/E13*100) -> 40.372671
B14: MA | C14: Versailles | D14: 138 | E14: 138 | F14: 137 | G14: =IF(E14=0,0,F14/E14*100) -> 99.275362
B15: MA | C15: Villepinte | D15: 587 | E15: 587 | F15: 1012 | G15: =IF(E15=0,0,F15/E15*100) -> 172.40204
B16: qMA | C16: Fresnes (**) | D16: 1404 | E16: 1404 | F16: 2368 | G16: =IF(E16=0,0,F16/E16*100) -> 168.66097
B17: qMA | C17: Meaux-Chauconin | D17: 385 | E17: 385 | F17: 682 | G17: =IF(E17=0,0,F17/E17*100) -> 177.14286
B18: Ensemble des Maisons d'Arrêt et qMA | D18: 7525 | E18: 7525 | F18: 11191 | G18: =IF(E18=0,0,F18/E18*100) -> 148.71761
B19: CD | C19: Melun | D19: 310 | E19: 308 | F19: 284 | G19: =IF(E19=0,0,F19/E19*100) -> 92.207792
B20: qCD | C20: Meaux-Chauconin | D20: 192 | E20: 192 | F20: 174 | G20: =IF(E20=0,0,F20/E20*100) -> 90.625
B21: qCD | C21: Sud Francilien | D21: 537 | E21: 537 | F21: 451 | G21: =IF(E21=0,0,F21/E21*100) -> 83.985102
B22: MC | C22: Poissy | D22: 314 | E22: 235 | F22: 221 | G22: =IF(E22=0,0,F22/E22*100) -> 94.042553
B23: qMC | C23: Sud Francilien | D23: 28 | E23: 28 | F23: 25 | G23: =IF(E23=0,0,F23/E23*100) -> 89.285714
B24: qCPA | C24: Fresnes (Villejuif) | D24: 116 | E24: 116 | F24: 134 | G24: =IF(E24=0,0,F24/E24*100) -> 115.51724
B25: qCPA | C25: Meaux-Chauconin | D25: 60 | E25: 60 | F25: 80 | G25: =IF(E25=0,0,F25/E25*100) -> 133.33333
B26: CSL | C26: Corbeil | D26: 77 | E26: 77 | F26: 113 | G26: =IF(E26=0,0,F26/E26*100) -> 146.75325
B27: CSL | C27: Gagny | D27: 48 | E27: 48 | F27: 103 | G27: =IF(E27=0,0,F27/E27*100) -> 214.58333
B28: CSL | C28: Melun | D28: 43 | E28: 43 | F28: 54 | G28: =IF(E28=0,0,F28/E28*100) -> 125.5814
B29: qCSL | C29: Fresnes (Villejuif) | D29: 27 | E29: 27 | F29: 29 | G29: =IF(E29=0,0,F29/E29*100) -> 107.40741
B30: EPM | C30: Porcheville | D30: 60 | E30: 60 | F30: 54 | G30: =IF(E30=0,0,F30/E30*100) -> 90
... B32: qCNE | C32: Sud Francilien | D32: 231 | E32: 231 | F32: 162 | G32: =IF(E32=0,0,F32/E32*100) -> 70.12987
B33: Ensemble des établissements pour peine* | D33: 2100 | E33: 2019 | F33: 1913 | G33: =IF(E33=0,0,F33/E33*100) -> 94.749876
B34: Ensemble de la Direction Régionale | D34: 9625 | E34: 9544 | F34: 13104 | G34: =IF(E34=0,0,F34/E34*100) -> 137.30092
B35: q = quartier
B36: *article D70 du code de procédure pénale
B37: ** y compris l'E.P.S.N

Sheet tab20 Rennes
B1: Tableau 20
B2: Population écrouée détenue par établissement | F2: Direction Interrégionale de Rennes
A4: Effectif au : | B4: =couverture!D15 -> 1er juillet 2014
A5: Source : | B5: DAP - PMJ5
A6: Capacités au : | B6: =couverture!D15 -> 1er juillet 2014
B7: (source DAP - EMS1)
D8: Capacité norme circulaire | E8: Capacité opérationnelle | F8: Nombre de personnes écrouées détenues | G8: Densité (%)
B9: MA | C9: Angers | D9: 266 | E9: 266 | F9: 384 | G9: =IF(E9=0,0,F9/E9*100) -> 144.3609
B10: MA | C10: Brest | D10: 254 | E10: 254 | F10: 336 | G10: =IF(E10=0,0,F10/E10*100) -> 132.28346
B11: MA | C11: Caen | D11: 269 | E11: 269 | F11: 398 | G11: =IF(E11=0,0,F11/E11*100) -> 147.95539
B12: MA | C12: Cherbourg | D12: 46 | E12: 46 | F12: 91 | G12: =IF(E12=0,0,F12/E12*100) -> 197.82609
B13: MA | C13: Coutances | D13: 48 | E13: 48 | F13: 86 | G13: =IF(E13=0,0,F13/E13*100) -> 179.16667
B14: MA | C14: Fontenay-le-Comte | D14: 39 | E14: 39 | F14: 80 | G14: =IF(E14=0,0,F14/E14*100) -> 205.12821
B15: MA | C15: La Roche-sur-Yon | D15: 39 | E15: 39 | F15: 80 | G15: =IF(E15=0,0,F15/E15*100) -> 205.12821
B16: MA | C16: Laval | D16: 71 | E16: 71 | F16: 128 | G16: =IF(E16=0,0,F16/E16*100) -> 180.28169
B17: MA | C17: Le Mans-Croisettes | D17: 401 | E17: 401 | F17: 499 | G17: =IF(E17=0,0,F17/E17*100) -> 124.4389
B18: MA | C18: Saint Malo | D18: 92 | E18: 92 | F18: 118 | G18: =IF(E18=0,0,F18/E18*100) -> 128.26087
B19: MA | C19: Saint-Brieuc | D19: 85 | E19: 85 | F19: 163 | G19: =IF(E19=0,0,F19/E19*100) -> 191.76471
B20: MA | C20: Vannes | D20: 52 | E20: 52 | F20: 91 | G20: =IF(E20=0,0,F20/E20*100) -> 175
... B25: qMA | C25: Rennes-Vezin | D25: 480 | E25: 480 | F25: 634 | G25: =IF(E25=0,0,F25/E25*100) -> 132.08333
B26: Ensemble des Maisons d'Arrêt et qMA | D26: 2979 | E26: 2979 | F26: 4095 | G26: =IF(E26=0,0,F26/E26*100) -> 137.46224
B27: CD | C27: Argentan | D27: 638 | E27: 638 | F27: 600 | G27: =IF(E27=0,0,F27/E27*100) -> 94.043887
B28: qCD | C28: Caen | D28: 448 | E28: 422 | F28: 364 | G28: =IF(E28=0,0,F28/E28*100) -> 86.255924
B29: qCD | C29: Lorient-Ploemeur | D29: 40 | E29: 40 | F29: 37 | G29: =IF(E29=0,0,F29/E29*100) -> 92.5
B30: qCD | C30: Nantes | D30: 510 | E30: 414 | F30: 399 | G30: =IF(E30=0,0,F30/E30*100) -> 96.376812
B31: qCD | C31: Rennes | D31: 232 | E31: 232 | F31: 187 | G31: =IF(E31=0,0,F31/E31*100) -> 80.603448
B32: qCD | C32: Rennes-Vezin | D32: 210 | E32: 210 | F32: 199 | G32: =IF(E32=0,0,F32/E32*100) -> 94.761905
B33: qMC | C33: Alençon-Condé-sur-Sarthe | D33: 204 | E33: 204 | F33: 71 | G33: =IF(E33=0,0,F33/E33*100) -> 34.803922
B34: qCPA | C34: Alençon-Condé-sur-Sarthe | D34: 45 | E34: 45 | F34: 23 | G34: =IF(E34=0,0,F34/E34*100) -> 51.111111
B35: qCSL | C35: Caen | D35: 50 | E35: 50 | F35: 36 | G35: =IF(E35=0,0,F35/E35*100) -> 72
B36: qCSL | C36: Nantes | D36: 36 | E36: 36 | F36: 28 | G36: =IF(E36=0,0,F36/E36*100) -> 77.777778
B37: qCSL | C37: Rennes-Vezin | D37: 26 | E37: 26 | F37: 12 | G37: =IF(E37=0,0,F37/E37*100) -> 46.153846
B38: EPM | C38: Orvault | D38: 59 | E38: 55 | F38: 39 | G38: =IF(E38=0,0,F38/E38*100) -> 70.909091
B39: Ensemble des établissements pour peine* | D39: 2498 | E39: 2372 | F39: 1995 | G39: =IF(E39=0,0,F39/E39*100) -> 84.106239
B40: Ensemble de la Direction Régionale | D40: 5477 | E40: 5351 | F40: 6090 | G40: =IF(E40=0,0,F40/E40*100) -> 113.8105
B41: q = quartier
B42: *article D70 du code de procédure pénale

Sheet tab21 Strasbourg
B1: Tableau 21
B2: Population écrouée détenue par établissement | F2: Direction Interrégionale de Strasbourg
A4: Effectif au : | B4: =couverture!D15 -> 1er juillet 2014
A5: Source : | B5: DAP - PMJ5
A6: Capacités au : | B6: =couverture!D15 -> 1er juillet 2014
B7: (source DAP - EMS1)
D8: Capacité norme circulaire | E8: Capacité opérationnelle | F8: Nombre de personnes écrouées détenues | G8: Densité (%)
B9: MA | C9: Bar-le-Duc | D9: 73 | E9: 73 | F9: 76 | G9: =IF(E9=0,0,F9/E9*100) -> 104.10959
B10: MA | C10: Belfort | D10: 39 | E10: 39 | F10: 47 | G10: =IF(E10=0,0,F10/E10*100) -> 120.51282
B11: MA | C11: Besançon | D11: 275 | E11: 255 | F11: 286 | G11: =IF(E11=0,0,F11/E11*100) -> 112.15686
B12: MA | C12: Colmar | D12: 120 | E12: 120 | F12: 188 | G12: =IF(E12=0,0,F12/E12*100) -> 156.66667
B13: MA | C13: Epinal | D13: 294 | E13: 294 | F13: 279 | G13: =IF(E13=0,0,F13/E13*100) -> 94.897959
B14: MA | C14: Lons-le-Saunier | D14: 39 | E14: 39 | F14: 53 | G14: =IF(E14=0,0,F14/E14*100) -> 135.89744
B15: MA | C15: Lure | D15: 73 | E15: 0 | F15: 0 | G15: =IF(E15=0,0,F15/E15*100) -> 0
B16: MA | C16: Montbéliard | D16: 41 | E16: 41 | F16: 54 | G16: =IF(E16=0,0,F16/E16*100) -> 131.70732
B17: MA | C17: Mulhouse | D17: 283 | E17: 283 | F17: 390 | G17: =IF(E17=0,0,F17/E17*100) -> 137.80919
B18: MA | C18: Sarreguemines | D18: 71 | E18: 71 | F18: 96 | G18: =IF(E18=0,0,F18/E18*100) -> 135.21127
B19: MA | C19: Strasbourg | D19: 445 | E19: 445 | F19: 758 | G19: =IF(E19=0,0,F19/E19*100) -> 170.33708
B20: MA | C20: Vesoul | D20: 50 | E20: 50 | F20: 34 | G20: =IF(E20=0,0,F20/E20*100) -> 68
... B22: qMA | C22: Nancy Maxéville | D22: 452 | E22: 452 | F22: 625 | G22: =IF(E22=0,0,F22/E22*100) -> 138.27434
B23: Ensemble des Maisons d'Arrêt et qMA | D23: 2659 | E23: 2566 | F23: 3458 | G23: =IF(E23=0,0,F23/E23*100) -> 134.76228
B24: CD | C24: Ecrouves | D24: 269 | E24: 269 | F24: 237 | G24: =IF(E24=0,0,F24/E24*100) -> 88.104089
B25: CD | C25: Montmédy | D25: 366 | E25: 326 | F25: 276 | G25: =IF(E25=0,0,F25/E25*100) -> 84.662577
B26: CD | C26: Oermingen | D26: 268 | E26: 263 | F26: 258 | G26: =IF(E26=0,0,F26/E26*100) -> 98.098859
B27: CD | C27: Saint-Mihiel | D27: 400 | E27: 400 | F27: 360 | G27: =IF(E27=0,0,F27/E27*100) -> 90
B28: CD | C28: Toul | D28: 429 | E28: 429 | F28: 405 | G28: =IF(E28=0,0,F28/E28*100) -> 94.405594
B29: qCD | C29: Nancy Maxéville | D29: 240 | E29: 240 | F29: 217 | G29: =IF(E29=0,0,F29/E29*100) -> 90.416667
B30: MC | C30: Ensisheim | D30: 215 | E30: 200 | F30: 190 | G30: =IF(E30=0,0,F30/E30*100) -> 95
B31: qCPA | C31: Metz-Queuleu | D31: 77 | E31: 77 | F31: 52 | G31: =IF(E31=0,0,F31/E31*100) -> 67.532468
B32: CSL | C32: Besançon | D32: 23 | E32: 23 | F32: 11 | G32: =IF(E32=0,0,F32/E32*100) -> 47.826087
B33: CSL | C33: Briey | D33: 25 | E33: 25 | F33: 14 | G33: =IF(E33=0,0,F33/E33*100) -> 56
B34: CSL | C34: Maxéville | D34: 56 | E34: 56 | F34: 35 | G34: =IF(E34=0,0,F34/E34*100) -> 62.5
B35: CSL | C35: Souffelweyersheim | D35: 53 | E35: 53 | F35: 49 | G35: =IF(E35=0,0,F35/E35*100) -> 92.45283
B36: Ensemble des établissements pour peine* | D36: 2421 | E36: 2361 | F36: 2104 | G36: =IF(E36=0,0,F36/E36*100) -> 89.114782
B37: Ensemble de la Direction Régionale | D37: 5080 | E37: 4927 | F37: 5562 | G37: =IF(E37=0,0,F37/E37*100) -> 112.88817
B38: q = quartier
B39: *article D70 du code de procédure pénale

Sheet tab22 Toulouse
B1: Tableau 22
B2: Population écrouée détenue par établissement | F2: Direction Interrégionale de Toulouse
A4: Effectif au : | B4: =couverture!D15 -> 1er juillet 2014
A5: Source : | B5: DAP - PMJ5
A6: Capacités au : | B6: =couverture!D15 -> 1er juillet 2014
B7: (source DAP - EMS1)
D8: Capacité norme circulaire | E8: Capacité opérationnelle | F8: Nombre de personnes écrouées détenues | G8: Densité (%)
B9: MA | C9: Albi | D9: 105 | E9: 105 | F9: 144 | G9: =IF(E9=0,0,F9/E9*100) -> 137.14286
B10: MA | C10: Carcassonne | D10: 66 | E10: 66 | F10: 109 | G10: =IF(E10=0,0,F10/E10*100) -> 165.15152
B11: MA | C11: Foix | D11: 66 | E11: 64 | F11: 92 | G11: =IF(E11=0,0,F11/E11*100) -> 143.75
B12: MA | C12: Mende | D12: 45 | E12: 45 | F12: 55 | G12: =IF(E12=0,0,F12/E12*100) -> 122.22222
B13: MA | C13: Montauban | D13: 144 | E13: 144 | F13: 184 | G13: =IF(E13=0,0,F13/E13*100) -> 127.77778
B14: MA | C14: Nîmes | D14: 192 | E14: 192 | F14: 414 | G14: =IF(E14=0,0,F14/E14*100) -> 215.625
B15: MA | C15: Rodez | D15: 100 | E15: 100 | F15: 86 | G15: =IF(E15=0,0,F15/E15*100) -> 86
B16: MA | C16: Tarbes | D16: 69 | E16: 69 | F16: 110 | G16: =IF(E16=0,0,F16/E16*100) -> 159.42029
B17: qMA | C17: Béziers | D17: 416 | E17: 416 | F17: 524 | G17: =IF(E17=0,0,F17/E17*100) -> 125.96154
B18: qMA | C18: Perpignan | D18: 204 | E18: 204 | F18: 350 | G18: =IF(E18=0,0,F18/E18*100) -> 171.56863
B19: qMA | C19: Toulouse-Seysses | D19: 651 | E19: 651 | F19: 926 | G19: =IF(E19=0,0,F19/E19*100) -> 142.2427
B20: qMA | C20: Villeneuve-lès-Maguelone | D20: 593 | E20: 593 | F20: 790 | G20: =IF(E20=0,0,F20/E20*100) -> 133.22091
B21: Ensemble des Maisons d'Arrêt et qMA | D21: 2651 | E21: 2649 | F21: 3784 | G21: =IF(E21=0,0,F21/E21*100) -> 142.84636
B22: CD | C22: Muret | D22: 657 | E22: 620 | F22: 584 | G22: =IF(E22=0,0,F22/E22*100) -> 94.193548
B23: CD | C23: Saint-Sulpice-la-Pointe | D23: 102 | E23: 102 | F23: 86 | G23: =IF(E23=0,0,F23/E23*100) -> 84.313725
B24: qCD | C24: Béziers | D24: 393 | E24: 393 | F24: 393 | G24: =IF(E24=0,0,F24/E24*100) -> 100
B25: qCD | C25: Lannemezan | D25: 20 | E25: 10 | F25: 4 | G25: =IF(E25=0,0,F25/E25*100) -> 40
B26: qCD | C26: Perpignan | D26: 333 | E26: 333 | F26: 325 | G26: =IF(E26=0,0,F26/E26*100) -> 97.597598
B27: qMC | C27: Lannemezan | D27: 212 | E27: 162 | F27: 121 | G27: =IF(E27=0,0,F27/E27*100) -> 74.691358
B28: qCSL | C28: Toulouse-Seysses | D28: 101 | E28: 52 | F28: 44 | G28: =IF(E28=0,0,F28/E28*100) -> 84.615385
B29: qCSL | C29: Villeneuve-lès-Maguelone | D29: 24 | E29: 24 | F29: 20 | G29: =IF(E29=0,0,F29/E29*100) -> 83.333333
B30: EPM | C30: Lavaur | D30: 59 | E30: 59 | F30: 43 | G30: =IF(E30=0,0,F30/E30*100) -> 72.881356
B31: Ensemble des établissements pour peine* | D31: 1901 | E31: 1755 | F31: 1620 | G31: =IF(E31=0,0,F31/E31*100) -> 92.307692
B32: Ensemble de la Direction Régionale | D32: 4552 | E32: 4404 | F32: 5404 | G32: =IF(E32=0,0,F32/E32*100) -> 122.70663
B33: q = quartier
B34: *article D70 du code de procédure pénale

Sheet tab23 DOM
B1: Tableau 23
B2: Population écrouée détenue par établissement | E2: Mission Outre-Mer
A4: Effectif au : | B4: =couverture!D15 -> 1er juillet 2014
A5: Source : | B5: DAP - PMJ5
A6: Capacités au : | B6: =couverture!D15 -> 1er juillet 2014
B7: (source DAP - EMS1)
D8: Capacité norme circulaire | E8: Capacité opérationnelle | F8: Nombre de personnes écrouées détenues | G8: Densité (%)
A9: MA et qMA | B9: MA | C9: Basse-Terre | D9: 130 | E9: 130 | F9: 184 | G9: =IF(E9=0,0,F9/E9*100) -> 141.53846
B10: qMA | C10: Baie-Mahault | D10: 266 | E10: 266 | F10: 464 | G10: =IF(E10=0,0,F10/E10*100) -> 174.43609
A11: ANTILLES ET GUYANE | B11: qMA | C11: Ducos | D11: 211 | E11: 211 | F11: 453 | G11: =IF(E11=0,0,F11/E11*100) -> 214.69194
B12: qMA | C12: Guyane (Remiré Montjoly) | D12: 310 | E12: 310 | F12: 409 | G12: =IF(E12=0,0,F12/E12*100) -> 131.93548
B13: MA | C13: Saint-Pierre | D13: 123 | E13: 123 | F13: 122 | G13: =IF(E13=0,0,F13/E13*100) -> 99.186992
B14: qMA | C14: Saint-Denis | D14: 558 | E14: 558 | F14: 489 | G14: =IF(E14=0,0,F14/E14*100) -> 87.634409
A15: OCEANS INDIEN ET | B15: qMA | C15: Saint-Pierre-et-Miquelon | D15: 7 | E15: 7 | F15: 4 | G15: =IF(E15=0,0,F15/E15*100) -> 57.142857
A16: PACIFIQUE | B16: MA | C16: Majicavo | D16: 162 | E16: 162 | F16: 157 | G16: =IF(E16=0,0,F16/E16*100) -> 96.91358
A17: et Saint Pierre et Miquelon | B17: MA | C17: Mata Utu | D17: 3 | E17: 3 | F17: 3 | G17: =IF(E17=0,0,F17/E17*100) -> 100
B18: MA | C18: Taiohae | D18: 5 | E18: 5 | F18: 3 | G18: =IF(E18=0,0,F18/E18*100) -> 60
B19: MA | C19: Uturoa-Raiatea | D19: 20 | E19: 20 | F19: 14 | G19: =IF(E19=0,0,F19/E19*100) -> 70
B20: qMA | C20: Faa'a Nuutania | D20: 54 | E20: 54 | F20: 162 | G20: =IF(E20=0,0,F20/E20*100) -> 300
B21: qMA | C21: Nouméa | D21: 184 | E21: 184 | F21: 212 | G21: =IF(E21=0,0,F21/E21*100) -> 115.21739
B22: Ensemble des Maisons d'Arrêt et qMA | D22: 2033 | E22: 2033 | F22: 2676 | G22: =IF(E22=0,0,F22/E22*100) -> 131.62814
A23: Etablissements | B23: qCD | C23: Baie-Mahault | D23: 238 | E23: 238 | F23: 231 | G23: =IF(E23=0,0,F23/E23*100) -> 97.058824
A24: et quartiers pour peine | B24: qCD | C24: Ducos | D24: 358 | E24: 358 | F24: 443 | G24: =IF(E24=0,0,F24/E24*100) -> 123.74302
A25: ANTILLES ET GUYANE | B25: qCD | C25: Guyane (Remiré Montjoly) | D25: 304 | E25: 304 | F25: 295 | G25: =IF(E25=0,0,F25/E25*100) -> 97.039474
B26: CD | C26: Le Port (Plaine les Galets) | D26: 560 | E26: 508 | F26: 473 | G26: =IF(E26=0,0,F26/E26*100) -> 93.110236
A27: OCEANS INDIEN ET | B27: qCD | C27: Saint-Denis | D27: 17 | E27: 17 | F27: 16 | G27: =IF(E27=0,0,F27/E27*100) -> 94.117647
A28: PACIFIQUE | B28: qCD | C28: Saint-Pierre-et-Miquelon | D28: 4 | E28: 4 | F28: 1 | G28: =IF(E28=0,0,F28/E28*100) -> 25
A29: et Saint Pierre et Miquelon | B29: qCD | C29: Faa'a Nuutania | D29: 111 | E29: 111 | F29: 235 | G29: =IF(E29=0,0,F29/E29*100) -> 211.71171
B30: qCD | C30: Nouméa | D30: 197 | E30: 197 | F30: 241 | G30: =IF(E30=0,0,F30/E30*100) -> 122.33503
B31: Ensemble des établissements pour peine* | D31: 1789 | E31: 1737 | F31: 1935 | G31: =IF(E31=0,0,F31/E31*100) -> 111.39896
B32: Ensemble de la Direction Régionale | D32: 3822 | E32: 3770 | F32: 4611 | G32: =IF(E32=0,0,F32/E32*100) -> 122.30769
B33: q = quartier
B34: *article D70 du code de procédure pénale

Sheet tab26 DRsexe
B1: Tableau 26
B2: Nombre de personnes écrouées détenues par sexe et par Direction Interrégionale
A5: Champ : | B5: Métropole et Outre-Mer
A6: Effectif au : | B6: =couverture!D15 -> 1er juillet 2014
A7: Source : | B7: DAP - PMJ5
C11: Hommes | D11: Femmes | E11: Nombre de personnes écrouées détenues | F11: Taux de féminité (%)
B12: Bordeaux | C12: 5034 | D12: 146 | E12: =SUM(C12:D12) -> 5180 | F12: =D12/E12*100 -> 2.8185328
B13: Dijon | C13: 4890 | D13: 177 | E13: =SUM(C13:D13) -> 5067 | F13: =D13/E13*100 -> 3.4931912
B14: Lille | C14: 9169 | D14: 304 | E14: =SUM(C14:D14) -> 9473 | F14: =D14/E14*100 -> 3.2091207
B15: Lyon | C15: 5678 | D15: 206 | E15: =SUM(C15:D15) -> 5884 | F15: =D15/E15*100 -> 3.5010197
B16: Marseille | C16: 7765 | D16: 155 | E16: =SUM(C16:D16) -> 7920 | F16: =D16/E16*100 -> 1.9570707
B17: Paris | C17: 12588 | D17: 516 | E17: =SUM(C17:D17) -> 13104 | F17: =D17/E17*100 -> 3.9377289
B18: Rennes | C18: 5755 | D18: 335 | E18: =SUM(C18:D18) -> 6090 | F18: =D18/E18*100 -> 5.500821
B19: Strasbourg | C19: 5402 | D19: 160 | E19: =SUM(C19:D19) -> 5562 | F19: =D19/E19*100 -> 2.8766631
B20: Toulouse | C20: 5255 | D20: 149 | E20: =SUM(C20:D20) -> 5404 | F20: =D20/E20*100 -> 2.7572169
B22: Ensemble de la métropole | C22: =SUM(C12:C20) -> 61536 | D22: =SUM(D12:D20) -> 2148 | E22: =SUM(E12:E20) -> 63684 | F22: =D22/E22*100 -> 3.3729037
B24: Outre Mer | C24: 4477 | D24: 134 | E24: =SUM(C24:D24) -> 4611 | F24: =D24/E24*100 -> 2.9060941
B27: Ensemble des établissements pénitentiaires | C27: =SUM(C22,C24:C25) -> 66013 | D27: =SUM(D22,D24:D25) -> 2282 | E27: =SUM(E22,E24:E25) -> 68295 | F27: =D27/E27*100 -> 3.3413866

Sheet tab27 mineurs
B1: Tableau 27
B2: Nombre et pourcentage de mineurs écroués détenus
A5: Champ : | B5: Métropole et Outre-Mer
A6: Effectif au : | B6: =couverture!D15 -> 1er juillet 2014
A7: Source : | B7: DAP - PMJ5
C10: Nombre de mineurs écroués détenus | D10: Nombre de personnes écrouées détenues | E10: Proportion de mineurs écroués détenus (%)
B11: Métropole | C11: 734 | D11: 63684 | E11: =C11/D11*100 -> 1.1525658
B12: Outre Mer | C12: 60 | D12: 4611 | E12: =C12/D12*100 -> 1.3012362
B15: Ensemble | C15: =SUM(C11:C13) -> 794 | D15: =SUM(D11:D13) -> 68295 | E15: =C15/D15*100 -> 1.1626034

Sheet tab28 mineurs.cat.pén
B1: Tableau 28
B2: Nombre et pourcentage de mineurs écroués détenus selon la catégorie pénale
A5: Champ : | B5: Métropole et Outre-Mer
A6: Effectif au : | B6: =couverture!D15 -> 1er juillet 2014
A7: Source : | B7: DAP - PMJ5
C10: Métropole | E10: Outre-Mer | G10: Ensemble
C11: Effectifs | D11: % | E11: Effectifs | F11: % | G11: Effectifs | H11: %
B13: Prévenus | C13: 469 | D13: =C13/$C$16*100 -> 63.896458 | E13: 34 | F13: =E13/$E$16*100 -> 56.666667 | G13: =C13+E13 -> 503 | H13: =G13/$G$16*100 -> 63.350126
B14: Condamnés | C14: 265 | D14: =C14/$C$16*100 -> 36.103542 | E14: 26 | F14: =E14/$E$16*100 -> 43.333333 | G14: =C14+E14 -> 291 | H14: =G14/$G$16*100 -> 36.649874
B16: Ensemble | C16: =SUM(C13:C14) -> 734 | D16: =SUM(D13:D14) -> 100 | E16: =SUM(E13:E14) -> 60 | F16: =SUM(F13:F14) -> 100 | G16: =SUM(G13:G14) -> 794 | H16: =SUM(H13:H14) -> 100

Sheet tab29mineurs.évol
B1: Tableau 29
B2: Evolution mensuelle du nombre de mineurs écroués détenus sur deux années
A4: Champ : | B4: Métropole et Outre-Mer
A5: Effectif au : | B5: ='tab28 mineurs.cat.pén'!B6 -> 1er juillet 2014
A6: Source : | B6: DAP - PMJ5
B8: Situation au 1er du mois | C8: Prévenus | D8: Condamnés | E8: Ensemble | F8: Variation mensuelle (%)
B9: juillet 2012 | C9: 493 | D9: 317 | E9: 810 | F9: 0.051948052
B10: août 2012 | C10: 436 | D10: 319 | E10: 755 | F10: -0.067901235
B11: septembre 2012 | C11: 395 | D11: 285 | E11: 680 | F11: -0.099337748
B12: octobre 2012 | C12: 422 | D12: 245 | E12: 667 | F12: -0.019117647
B13: novembre 2012 | C13: 431 | D13: 250 | E13: 681 | F13: 0.020989505
B14: décembre 2012 | C14: 450 | D14: 273 | E14: 723 | F14: 0.061674009
B15: janvier 2013 | C15: 439 | D15: 285 | E15: 724 | F15: 0.0013831259
B16: février 2013 | C16: 476 | D16: 245 | E16: 721 | F16: -0.0041436464
B17: mars 2013 | C17: 486 | D17: 243 | E17: 729 | F17: 0.0110957
B18: avril 2013 | C18: 493 | D18: 249 | E18: 742 | F18: 0.017832647
B19: mai 2013 | C19: 477 | D19: 294 | E19: 771 | F19: 0.039083558
B20: juin 2013 | C20: 506 | D20: 272 | E20: 778 | F20: 0.009079118
... B33: juillet 2014 | C33: 503 | D33: 291 | E33: 794 | F33: -0.018541409

Sheet tab30 courbe
B1: Tableau 30
B2: Evolution mensuelle du nombre de mineurs écroués détenus
A3: Evolution mensuelle de la population écrouée détenue mineure depuis le 1er janvier 2012
A4: Champ : | B4: Métropole et Outre-Mer
A5: Effectif au : | B5: =couverture!D15 -> 1er juillet 2014
A6: Source : | B6: DAP - PMJ5

Sheet tab31 mineurs.étab
B1: Tableau 31
B2: Nombre de mineurs écroués détenus par établissement
A4: Champ : | B4: Métropole et Outre-Mer
A5: Effectif au : | B5: =couverture!D15 -> 1er juillet 2014
A6: Source : | B6: DAP - PMJ5
B8: Etablissement | D8: Nombre de mineurs écroués détenus | E8: Nombre de jeunes majeurs occupant des places mineurs | F8: Nombre de places mineurs (source EMS1) | G8: Taux d'occupation des places mineurs
B9: CP | C9: Bordeaux Gradignan | D9: 17 | E9: 0 | F9: 23 | G9: =IF(F9=0,"-",(D9+E9)/F9) -> 0.73913043
B10: MA | C10: Angoulême | D10: 6 | E10: 0 | F10: 7 | G10: =IF(F10=0,"-",(D10+E10)/F10) -> 0.85714286
B11: MA | C11: Limoges | D11: 8 | E11: 0 | F11: 12 | G11: =IF(F11=0,"-",(D11+E11)/F11) -> 0.66666667
B12: MA | C12: Pau | D12: 5 | E12: 0 | F12: 10 | G12: =IF(F12=0,"-",(D12+E12)/F12) -> 0.5
B13: Ensemble de la DI de Bordeaux | D13: 36 | E13: 0 | F13: 52 | G13: =IF(F13=0,"-",(D13+E13)/F13) -> 0.69230769
B14: CP | C14: Varennes-le-Grand | D14: 5 | E14: 0 | F14: 15 | G14: =IF(F14=0,"-",(D14+E14)/F14) -> 0.33333333
B15: MA | C15: Bourges | D15: 3 | E15: 0 | F15: 4 | G15: =IF(F15=0,"-",(D15+E15)/F15) -> 0.75
